<?xml version="1.0"?>
<robot name="humanoid_torso">
  <!-- Torso -->
  <link name="torso">
    <inertial>
      <mass value="5.0" />
      <origin xyz="0 0 0" rpy="0 0 0" />
      <inertia ixx="0.1" ixy="0.0" ixz="0.0" iyy="0.1" iyz="0.0" izz="0.1" />
    </inertial>
    <visual>
      <origin xyz="0 0 0" rpy="0 0 0" />
      <geometry>
        <box size="0.3 0.2 0.5" />
      </geometry>
      <material name="light_grey">
        <color rgba="0.7 0.7 0.7 1.0" />
      </material>
    </visual>
    <collision>
      <origin xyz="0 0 0" rpy="0 0 0" />
      <geometry>
        <box size="0.3 0.2 0.5" />
      </geometry>
    </collision>
  </link>

  <!-- Head -->
  <link name="head">
    <inertial>
      <mass value="1.0" />
      <origin xyz="0 0 0" rpy="0 0 0" />
      <inertia ixx="0.002" ixy="0.0" ixz="0.0" iyy="0.002" iyz="0.0" izz="0.002" />
    </inertial>
    <visual>
      <origin xyz="0 0 0" rpy="0 0 0" />
      <geometry>
        <sphere radius="0.1" />
      </geometry>
      <material name="white">
        <color rgba="1.0 1.0 1.0 1.0" />
      </material>
    </visual>
    <collision>
      <origin xyz="0 0 0" rpy="0 0 0" />
      <geometry>
        <sphere radius="0.1" />
      </geometry>
    </collision>
  </link>

  <!-- Joint connecting torso to head -->
  <joint name="torso_to_head" type="revolute">
    <parent link="torso" />
    <child link="head" />
    <origin xyz="0 0 0.35" rpy="0 0 0" />
    <axis xyz="0 0 1" />
    <limit lower="-1.57" upper="1.57" effort="10.0" velocity="1.0" />
  </joint>

  <!-- Left Upper Arm -->
  <link name="upper_arm_left">
    <inertial>
      <mass value="1.0" />
      <origin xyz="0 0 -0.15" rpy="0 0 0" />
      <inertia ixx="0.005" ixy="0.0" ixz="0.0" iyy="0.005" iyz="0.0" izz="0.0005" />
    </inertial>
    <visual>
      <origin xyz="0 0 -0.15" rpy="0 0 0" />
      <geometry>
        <cylinder length="0.3" radius="0.05" />
      </geometry>
      <material name="blue">
        <color rgba="0.0 0.0 1.0 1.0" />
      </material>
    </visual>
    <collision>
      <origin xyz="0 0 -0.15" rpy="0 0 0" />
      <geometry>
        <cylinder length="0.3" radius="0.05" />
      </geometry>
    </collision>
  </link>

  <!-- Joint connecting torso to left upper arm -->
  <joint name="shoulder_left" type="revolute">
    <parent link="torso" />
    <child link="upper_arm_left" />
    <origin xyz="0.2 0.1 0.1" rpy="0 0 0" />
    <axis xyz="0 1 0" />
    <limit lower="-1.57" upper="1.57" effort="10.0" velocity="1.0" />
  </joint>

  <!-- Left Lower Arm -->
  <link name="lower_arm_left">
    <inertial>
      <mass value="0.5" />
      <origin xyz="0 0 -0.125" rpy="0 0 0" />
      <inertia ixx="0.002" ixy="0.0" ixz="0.0" iyy="0.002" iyz="0.0" izz="0.0002" />
    </inertial>
    <visual>
      <origin xyz="0 0 -0.125" rpy="0 0 0" />
      <geometry>
        <cylinder length="0.25" radius="0.04" />
      </geometry>
      <material name="blue">
        <color rgba="0.0 0.0 1.0 1.0" />
      </material>
    </visual>
    <collision>
      <origin xyz="0 0 -0.125" rpy="0 0 0" />
      <geometry>
        <cylinder length="0.25" radius="0.04" />
      </geometry>
    </collision>
  </link>

  <!-- Joint connecting upper arm to lower arm -->
  <joint name="elbow_left" type="revolute">
    <parent link="upper_arm_left" />
    <child link="lower_arm_left" />
    <origin xyz="0 0 -0.3" rpy="0 0 0" />
    <axis xyz="0 1 0" />
    <limit lower="-1.57" upper="1.57" effort="5.0" velocity="1.0" />
  </joint>
</robot>